Workbook

Sheet Инструкция
A1: Финансовая модель «Всё по полкам!» — донат-валюта и доход (05.10.2026)
A3: Что это. Модель считает, сколько разработчик получает с одного установившего игру игрока (LTV) и с потока игроков за год:
A4: реклама (межстраничная и за награду) + покупки (первая покупка и повторные). Каталог покупок и алмазы — по дизайну
A5: Docs/Донат_валюта_ВсёПоПолкам_05-10.md (вариант «узкие алмазы») и экономике v7.
A7: Как пользоваться:
A8: 1. Лист «Допущения», ячейка B3 — выберите сценарий (Пессимистичный / База / Оптимистичный).
A9: 2. Синие числа — допущения, их можно менять. Жёлтые — главные, их стоит заменить своими данными из консоли Яндекс Игр
A10: (удержание D1/D7/D30, показы рекламы на игрока, eCPM, конверсия в платящих, установки в день).
A11: 3. Чёрные числа — формулы, их не трогать. Зелёные — ссылки на другой лист.
A12: 4. «Каталог» — цены и состав покупок, доли в первых и повторных покупках (из них считается средний чек).
A13: 5. «Алмазы» — откуда бесплатный игрок берёт алмазы, на что их тратит и хватает ли на «попробовать».
A14: 6. «Когорта» — один день установок, 365 дней жизни: удержание, платящие, доход по дням, накопленный LTV.
... A24: Собрано скриптом Tools/finmodel_build.py — правки структуры лучше вносить туда и пересобирать.

Sheet Допущения
A1: Допущения модели
A3: Сценарий (выберите): | B3: База
A5: Параметр | B5: Выбрано | C5: Пессимистичный | D5: База | E5: Оптимистичный | F5: Ед. | G5: Откуда / комментарий
A6: Новых игроков в день (установки) | B6: =INDEX(C6:E6,MATCH($B$3,$C$5:$E$5,0)) -> 1000 | C6: 300 | D6: 1000 | E6: 3000 | F6: чел. | G6: Подставьте свою цифру из консоли. Модель линейна по установкам.
A7: Удержание D1 | B7: =INDEX(C7:E7,MATCH($B$3,$C$5:$E$5,0)) -> 0.3 | C7: 0.22 | D7: 0.3 | E7: 0.38 | G7: Оценка для веб-казуальных головоломок; мобильные лидеры жанра — 35–45 %.
A8: Удержание D7 | B8: =INDEX(C8:E8,MATCH($B$3,$C$5:$E$5,0)) -> 0.12 | C8: 0.08 | D8: 0.12 | E8: 0.17 | G8: Оценка; цель — 15 %+.
A9: Удержание D30 | B9: =INDEX(C9:E9,MATCH($B$3,$C$5:$E$5,0)) -> 0.05 | C9: 0.03 | D9: 0.05 | E9: 0.08 | G9: Оценка; на мобильных хорошие головоломки 5–10 %.
A10: Удержание D90 | B10: =INDEX(C10:E10,MATCH($B$3,$C$5:$E$5,0)) -> 0.022 | C10: 0.012 | D10: 0.022 | E10: 0.04 | G10: Оценка.
A11: Удержание D180 | B11: =INDEX(C11:E11,MATCH($B$3,$C$5:$E$5,0)) -> 0.012 | C11: 0.006 | D11: 0.012 | E11: 0.025 | G11: Оценка.
A12: Удержание D365 | B12: =INDEX(C12:E12,MATCH($B$3,$C$5:$E$5,0)) -> 0.005 | C12: 0.002 | D12: 0.005 | E12: 0.012 | G12: Оценка.
A13: Межстраничная реклама: показов на игрока в день | B13: =INDEX(C13:E13,MATCH($B$3,$C$5:$E$5,0)) -> 3 | C13: 2.5 | D13: 3 | E13: 3.5 | F13: показ | G13: Платформа: не чаще раза в 60 с, с 4-го уровня; сессия ~15 мин.
A14: Видео за награду: показов на игрока в день | B14: =INDEX(C14:E14,MATCH($B$3,$C$5:$E$5,0)) -> 2.5 | C14: 1.5 | D14: 2.5 | E14: 3.5 | F14: показ | G14: Симулятор v7: смотрящий рекламу — 6,6 в день; смотрит ~40 % игроков.
A15: eCPM межстраничной, ₽ за 1 000 показов (валовый) | B15: =INDEX(C15:E15,MATCH($B$3,$C$5:$E$5,0)) -> 120 | C15: 80 | D15: 120 | E15: 180 | F15: ₽ | G15: Оценка. Возьмите из консоли («Доход по источникам» / показы × 1000).
A16: eCPM видео за награду, ₽ за 1 000 показов (валовый) | B16: =INDEX(C16:E16,MATCH($B$3,$C$5:$E$5,0)) -> 250 | C16: 150 | D16: 250 | E16: 400 | F16: ₽ | G16: Оценка; видео за награду обычно дороже межстраничной в 1,5–3 раза.
A17: Доля разработчика от рекламы | B17: =INDEX(C17:E17,MATCH($B$3,$C$5:$E$5,0)) -> 0.5 | C17: 0.5 | D17: 0.5 | E17: 0.5 | G17: Лицензионное соглашение Яндекс Игр: 50 % дохода Яндекса.
A18: Доля разработчика от покупок | B18: =INDEX(C18:E18,MATCH($B$3,$C$5:$E$5,0)) -> 0.5 | C18: 0.5 | D18: 0.5 | E18: 0.5 | G18: 50 % по соглашению; в части источников — до 70 %. Проверить договор.
A19: Конверсия в платящих за всю жизнь (от установок) | B19: =INDEX(C19:E19,MATCH($B$3,$C$5:$E$5,0)) -> 0.01 | C19: 0.005 | D19: 0.01 | E19: 0.02 | G19: Казуальные головоломки на мобильных ~2 % (wnhub: 1,96–2,38 %); в вебе ниже.
A20: Доля первых покупок в первые 14 дней | B20: =INDEX(C20:E20,MATCH($B$3,$C$5:$E$5,0)) -> 0.77 | C20: 0.77 | D20: 0.77 | E20: 0.77 | G20: 77 % платящих платят впервые в первые 2 недели (отраслевые данные).
A21: Платящие удерживаются лучше, во сколько раз | B21: =INDEX(C21:E21,MATCH($B$3,$C$5:$E$5,0)) -> 2.5 | C21: 2 | D21: 2.5 | E21: 3 | F21: раз | G21: Оценка: платящие играют дольше среднего в 2–3 раза.
A22: Повторных покупок на активного платящего за 30 дней | B22: =INDEX(C22:E22,MATCH($B$3,$C$5:$E$5,0)) -> 1 | C22: 0.6 | D22: 1 | E22: 1.4 | F22: шт. | G22: Оценка; по v7 моментов оплаты ~17 за «Лёгкий» у неплатящего.
A23: Доля платящих, купивших «Без рекламы» | B23: =INDEX(C23:E23,MATCH($B$3,$C$5:$E$5,0)) -> 0.15 | C23: 0.15 | D23: 0.15 | E23: 0.15 | G23: Оценка; убирает межстраничную рекламу у этих игроков.
A25: Производные (формулы)
A26: Скорость конверсии k (из доли в первые 14 дней) | B26: =-LN(1-Допущения!$B$20)/14 -> 0.10497686 | G26: Доля заплативших к дню d = конверсия × (1 − e^(−k·d)).
A27: Средний чек первой покупки, ₽ | B27: =Каталог!J25 -> 93.5
A28: Средний чек повторной покупки, ₽ | B28: =Каталог!K25 -> 145.31308
A29: Валовый доход с рекламы на игрока в день, ₽ | B29: =(Допущения!$B$13*Допущения!$B$15+Допущения!$B$14*Допущения!$B$16)/1000 -> 0.985
A30: Курс: монет за 1 ₽ (пакет «Горстка монет») | B30: =Каталог!D5/Каталог!C5 -> 20.408163
A31: Курс: алмазов за 1 ₽ (самый маленький пакет) | B31: =Каталог!E9/Каталог!C9 -> 1.0344828

Sheet Год
A1: Год: каждый день приходят новые игроки (месяц = 30 дней)
A2: Установок в день: | B2: =Допущения!$B$6 -> 1000
A4: Месяц | B4: Средний DAU | C4: Новых платящих | D4: Активных платящих (ср.) | E4: Реклама, ₽ (разраб.) | F4: Покупки, ₽ (разраб.) | G4: Итого разработчику, ₽ | H4: Валовый доход, ₽ | I4: ARPDAU разраб., ₽ | J4: Накопл. разработчику, ₽
A5: Месяц 1 | B5: =$B$2*SUM(INDEX(Когорта!$C$7:$C$371,1):INDEX(Когорта!$C$7:$C$371,30))/30 -> 2779.637 | C5: =$B$2*SUM(INDEX(Когорта!$D$7:$D$371,1):INDEX(Когорта!$D$7:$D$371,30)) -> 213.52767 | D5: =$B$2*SUM(INDEX(Когорта!$P$7:$P$371,1):INDEX(Когорта!$P$7:$P$371,30))/30 -> 23.497204 | E5: =$B$2*SUM(INDEX(Когорта!$L$7:$L$371,1):INDEX(Когорта!$L$7:$L$371,30)) -> 41050.103 | F5: =$B$2*(SUM(INDEX(Когорта!$M$7:$M$371,1):INDEX(Когорта!$M$7:$M$371,30))+SUM(INDEX(Когорта!$N$7:$N$371,1):INDEX(Когорта!$N$7:$N$371,30))) -> 11689.644 | G5: =E5+F5 -> 52739.748 | H5: =$B$2*SUM(INDEX(Когорта!$O$7:$O$371,1):INDEX(Когорта!$O$7:$O$371,30)) -> 105479.5 | I5: =IF(B5=0,0,G5/(B5*30)) -> 0.63245367 | J5: =G5 -> 52739.748
A6: Месяц 2 | B6: =$B$2*SUM(INDEX(Когорта!$C$7:$C$371,31):INDEX(Когорта!$C$7:$C$371,60))/30 -> 4455.385 | C6: =$B$2*SUM(INDEX(Когорта!$D$7:$D$371,31):INDEX(Когорта!$D$7:$D$371,60)) -> 296.2919 | D6: =$B$2*SUM(INDEX(Когорта!$P$7:$P$371,31):INDEX(Когорта!$P$7:$P$371,60))/30 -> 59.849144 | E6: =$B$2*SUM(INDEX(Когорта!$L$7:$L$371,31):INDEX(Когорта!$L$7:$L$371,60)) -> 65779.836 | F6: =$B$2*(SUM(INDEX(Когорта!$M$7:$M$371,31):INDEX(Когорта!$M$7:$M$371,60))+SUM(INDEX(Когорта!$N$7:$N$371,31):INDEX(Когорта!$N$7:$N$371,60))) -> 18200.078 | G6: =E6+F6 -> 83979.915 | H6: =$B$2*SUM(INDEX(Когорта!$O$7:$O$371,31):INDEX(Когорта!$O$7:$O$371,60)) -> 167959.83 | I6: =IF(B6=0,0,G6/(B6*30)) -> 0.62830271 | J6: =J5+G6 -> 136719.66
A7: Месяц 3 | B7: =$B$2*SUM(INDEX(Когорта!$C$7:$C$371,61):INDEX(Когорта!$C$7:$C$371,90))/30 -> 5375.625 | C7: =$B$2*SUM(INDEX(Когорта!$D$7:$D$371,61):INDEX(Когорта!$D$7:$D$371,90)) -> 299.84099 | D7: =$B$2*SUM(INDEX(Когорта!$P$7:$P$371,61):INDEX(Когорта!$P$7:$P$371,90))/30 -> 82.755961 | E7: =$B$2*SUM(INDEX(Когорта!$L$7:$L$371,61):INDEX(Когорта!$L$7:$L$371,90)) -> 79357.827 | F7: =$B$2*(SUM(INDEX(Когорта!$M$7:$M$371,61):INDEX(Когорта!$M$7:$M$371,90))+SUM(INDEX(Когорта!$N$7:$N$371,61):INDEX(Когорта!$N$7:$N$371,90))) -> 20030.328 | G7: =E7+F7 -> 99388.155 | H7: =$B$2*SUM(INDEX(Когорта!$O$7:$O$371,61):INDEX(Когорта!$O$7:$O$371,90)) -> 198776.31 | I7: =IF(B7=0,0,G7/(B7*30)) -> 0.61628899 | J7: =J6+G7 -> 236107.82
A8: Месяц 4 | B8: =$B$2*SUM(INDEX(Когорта!$C$7:$C$371,91):INDEX(Когорта!$C$7:$C$371,120))/30 -> 6040.091 | C8: =$B$2*SUM(INDEX(Когорта!$D$7:$D$371,91):INDEX(Когорта!$D$7:$D$371,120)) -> 299.99318 | D8: =$B$2*SUM(INDEX(Когорта!$P$7:$P$371,91):INDEX(Когорта!$P$7:$P$371,120))/30 -> 99.364735 | E8: =$B$2*SUM(INDEX(Когорта!$L$7:$L$371,91):INDEX(Когорта!$L$7:$L$371,120)) -> 89161.859 | F8: =$B$2*(SUM(INDEX(Когорта!$M$7:$M$371,91):INDEX(Когорта!$M$7:$M$371,120))+SUM(INDEX(Когорта!$N$7:$N$371,91):INDEX(Когорта!$N$7:$N$371,120))) -> 21244.179 | G8: =E8+F8 -> 110406.04 | H8: =$B$2*SUM(INDEX(Когорта!$O$7:$O$371,91):INDEX(Когорта!$O$7:$O$371,120)) -> 220812.08 | I8: =IF(B8=0,0,G8/(B8*30)) -> 0.60929567 | J8: =J7+G8 -> 346513.86
A9: Месяц 5 | B9: =$B$2*SUM(INDEX(Когорта!$C$7:$C$371,121):INDEX(Когорта!$C$7:$C$371,150))/30 -> 6557.7749 | C9: =$B$2*SUM(INDEX(Когорта!$D$7:$D$371,121):INDEX(Когорта!$D$7:$D$371,150)) -> 299.99971 | D9: =$B$2*SUM(INDEX(Когорта!$P$7:$P$371,121):INDEX(Когорта!$P$7:$P$371,150))/30 -> 112.30674 | E9: =$B$2*SUM(INDEX(Когорта!$L$7:$L$371,121):INDEX(Когорта!$L$7:$L$371,150)) -> 96800.156 | F9: =$B$2*(SUM(INDEX(Когорта!$M$7:$M$371,121):INDEX(Когорта!$M$7:$M$371,150))+SUM(INDEX(Когорта!$N$7:$N$371,121):INDEX(Когорта!$N$7:$N$371,150))) -> 22184.806 | G9: =E9+F9 -> 118984.96 | H9: =$B$2*SUM(INDEX(Когорта!$O$7:$O$371,121):INDEX(Когорта!$O$7:$O$371,150)) -> 237969.92 | I9: =IF(B9=0,0,G9/(B9*30)) -> 0.60480352 | J9: =J8+G9 -> 465498.82
A10: Месяц 6 | B10: =$B$2*SUM(INDEX(Когорта!$C$7:$C$371,151):INDEX(Когорта!$C$7:$C$371,180))/30 -> 6982.3393 | C10: =$B$2*SUM(INDEX(Когорта!$D$7:$D$371,151):INDEX(Когорта!$D$7:$D$371,180)) -> 299.99999 | D10: =$B$2*SUM(INDEX(Когорта!$P$7:$P$371,151):INDEX(Когорта!$P$7:$P$371,180))/30 -> 122.92084 | E10: =$B$2*SUM(INDEX(Когорта!$L$7:$L$371,151):INDEX(Когорта!$L$7:$L$371,180)) -> 103064.5 | F10: =$B$2*(SUM(INDEX(Когорта!$M$7:$M$371,151):INDEX(Когорта!$M$7:$M$371,180))+SUM(INDEX(Когорта!$N$7:$N$371,151):INDEX(Когорта!$N$7:$N$371,180))) -> 22956.003 | G10: =E10+F10 -> 126020.5 | H10: =$B$2*SUM(INDEX(Когорта!$O$7:$O$371,151):INDEX(Когорта!$O$7:$O$371,180)) -> 252041 | I10: =IF(B10=0,0,G10/(B10*30)) -> 0.60161547 | J10: =J9+G10 -> 591519.32
A11: Месяц 7 | B11: =$B$2*SUM(INDEX(Когорта!$C$7:$C$371,181):INDEX(Когорта!$C$7:$C$371,210))/30 -> 7340.5019 | C11: =$B$2*SUM(INDEX(Когорта!$D$7:$D$371,181):INDEX(Когорта!$D$7:$D$371,210)) -> 300 | D11: =$B$2*SUM(INDEX(Когорта!$P$7:$P$371,181):INDEX(Когорта!$P$7:$P$371,210))/30 -> 131.87491 | E11: =$B$2*SUM(INDEX(Когорта!$L$7:$L$371,181):INDEX(Когорта!$L$7:$L$371,210)) -> 108349.1 | F11: =$B$2*(SUM(INDEX(Когорта!$M$7:$M$371,181):INDEX(Когорта!$M$7:$M$371,210))+SUM(INDEX(Когорта!$N$7:$N$371,181):INDEX(Когорта!$N$7:$N$371,210))) -> 23606.575 | G11: =E11+F11 -> 131955.67 | H11: =$B$2*SUM(INDEX(Когорта!$O$7:$O$371,181):INDEX(Когорта!$O$7:$O$371,210)) -> 263911.34 | I11: =IF(B11=0,0,G11/(B11*30)) -> 0.59921276 | J11: =J10+G11 -> 723474.99
A12: Месяц 8 | B12: =$B$2*SUM(INDEX(Когорта!$C$7:$C$371,211):INDEX(Когорта!$C$7:$C$371,240))/30 -> 7639.3536 | C12: =$B$2*SUM(INDEX(Когорта!$D$7:$D$371,211):INDEX(Когорта!$D$7:$D$371,240)) -> 300 | D12: =$B$2*SUM(INDEX(Когорта!$P$7:$P$371,211):INDEX(Когорта!$P$7:$P$371,240))/30 -> 139.3462 | E12: =$B$2*SUM(INDEX(Когорта!$L$7:$L$371,211):INDEX(Когорта!$L$7:$L$371,240)) -> 112758.58 | F12: =$B$2*(SUM(INDEX(Когорта!$M$7:$M$371,211):INDEX(Когорта!$M$7:$M$371,240))+SUM(INDEX(Когорта!$N$7:$N$371,211):INDEX(Когорта!$N$7:$N$371,240))) -> 24149.413 | G12: =E12+F12 -> 136907.99 | H12: =$B$2*SUM(INDEX(Когорта!$O$7:$O$371,211):INDEX(Когорта!$O$7:$O$371,240)) -> 273815.98 | I12: =IF(B12=0,0,G12/(B12*30)) -> 0.59738035 | J12: =J11+G12 -> 860382.98
A13: Месяц 9 | B13: =$B$2*SUM(INDEX(Когорта!$C$7:$C$371,241):INDEX(Когорта!$C$7:$C$371,270))/30 -> 7892.3729 | C13: =$B$2*SUM(INDEX(Когорта!$D$7:$D$371,241):INDEX(Когорта!$D$7:$D$371,270)) -> 300 | D13: =$B$2*SUM(INDEX(Когорта!$P$7:$P$371,241):INDEX(Когорта!$P$7:$P$371,270))/30 -> 145.67169 | E13: =$B$2*SUM(INDEX(Когорта!$L$7:$L$371,241):INDEX(Когорта!$L$7:$L$371,270)) -> 116491.82 | F13: =$B$2*(SUM(INDEX(Когорта!$M$7:$M$371,241):INDEX(Когорта!$M$7:$M$371,270))+SUM(INDEX(Когорта!$N$7:$N$371,241):INDEX(Когорта!$N$7:$N$371,270))) -> 24609.001 | G13: =E13+F13 -> 141100.82 | H13: =$B$2*SUM(INDEX(Когорта!$O$7:$O$371,241):INDEX(Когорта!$O$7:$O$371,270)) -> 282201.63 | I13: =IF(B13=0,0,G13/(B13*30)) -> 0.59593745 | J13: =J12+G13 -> 1001483.8
A14: Месяц 10 | B14: =$B$2*SUM(INDEX(Когорта!$C$7:$C$371,271):INDEX(Когорта!$C$7:$C$371,300))/30 -> 8110.8848 | C14: =$B$2*SUM(INDEX(Когорта!$D$7:$D$371,271):INDEX(Когорта!$D$7:$D$371,300)) -> 300 | D14: =$B$2*SUM(INDEX(Когорта!$P$7:$P$371,271):INDEX(Когорта!$P$7:$P$371,300))/30 -> 151.13448 | E14: =$B$2*SUM(INDEX(Когорта!$L$7:$L$371,271):INDEX(Когорта!$L$7:$L$371,300)) -> 119715.9 | F14: =$B$2*(SUM(INDEX(Когорта!$M$7:$M$371,271):INDEX(Когорта!$M$7:$M$371,300))+SUM(INDEX(Когорта!$N$7:$N$371,271):INDEX(Когорта!$N$7:$N$371,300))) -> 25005.909 | G14: =E14+F14 -> 144721.81 | H14: =$B$2*SUM(INDEX(Когорта!$O$7:$O$371,271):INDEX(Когорта!$O$7:$O$371,300)) -> 289443.63 | I14: =IF(B14=0,0,G14/(B14*30)) -> 0.59476377 | J14: =J13+G14 -> 1146205.6
A15: Месяц 11 | B15: =$B$2*SUM(INDEX(Когорта!$C$7:$C$371,301):INDEX(Когорта!$C$7:$C$371,330))/30 -> 8302.563 | C15: =$B$2*SUM(INDEX(Когорта!$D$7:$D$371,301):INDEX(Когорта!$D$7:$D$371,330)) -> 300 | D15: =$B$2*SUM(INDEX(Когорта!$P$7:$P$371,301):INDEX(Когорта!$P$7:$P$371,330))/30 -> 155.92644 | E15: =$B$2*SUM(INDEX(Когорта!$L$7:$L$371,301):INDEX(Когорта!$L$7:$L$371,330)) -> 122544.07 | F15: =$B$2*(SUM(INDEX(Когорта!$M$7:$M$371,301):INDEX(Когорта!$M$7:$M$371,330))+SUM(INDEX(Когорта!$N$7:$N$371,301):INDEX(Когорта!$N$7:$N$371,330))) -> 25354.076 | G15: =E15+F15 -> 147898.14 | H15: =$B$2*SUM(INDEX(Когорта!$O$7:$O$371,301):INDEX(Когорта!$O$7:$O$371,330)) -> 295796.29 | I15: =IF(B15=0,0,G15/(B15*30)) -> 0.59378509 | J15: =J14+G15 -> 1294103.8
A16: Месяц 12 | B16: =$B$2*SUM(INDEX(Когорта!$C$7:$C$371,331):INDEX(Когорта!$C$7:$C$371,360))/30 -> 8472.8326 | C16: =$B$2*SUM(INDEX(Когорта!$D$7:$D$371,331):INDEX(Когорта!$D$7:$D$371,360)) -> 300 | D16: =$B$2*SUM(INDEX(Когорта!$P$7:$P$371,331):INDEX(Когорта!$P$7:$P$371,360))/30 -> 160.18318 | E16: =$B$2*SUM(INDEX(Когорта!$L$7:$L$371,331):INDEX(Когорта!$L$7:$L$371,360)) -> 125056.35 | F16: =$B$2*(SUM(INDEX(Когорта!$M$7:$M$371,331):INDEX(Когорта!$M$7:$M$371,360))+SUM(INDEX(Когорта!$N$7:$N$371,331):INDEX(Когорта!$N$7:$N$371,360))) -> 25663.356 | G16: =E16+F16 -> 150719.71 | H16: =$B$2*SUM(INDEX(Когорта!$O$7:$O$371,331):INDEX(Когорта!$O$7:$O$371,360)) -> 301439.42 | I16: =IF(B16=0,0,G16/(B16*30)) -> 0.59295286 | J16: =J15+G16 -> 1444823.5
A17: Итого за год | C17: =SUM(C5:C16) -> 3509.6534 | E17: =SUM(E5:E16) -> 1180130.1 | F17: =SUM(F5:F16) -> 264693.37 | G17: =SUM(G5:G16) -> 1444823.5 | H17: =SUM(H5:H16) -> 2889646.9
A19: Главные показатели
A20: Показатель | B20: Значение
A21: LTV разработчика на установку, D7 | B21: =INDEX(Когорта!$K$7:$K$371,8) -> 1.3982
A22: LTV, D30 | B22: =INDEX(Когорта!$K$7:$K$371,31) -> 2.4606946
A23: LTV, D90 | B23: =INDEX(Когорта!$K$7:$K$371,91) -> 3.5193372
A24: LTV, D365 | B24: =INDEX(Когорта!$K$7:$K$371,365) -> 5.0801981
A25: Доля покупок в LTV D365 | B25: =IF(B24=0,0,(INDEX(Когорта!$M$7:$M$371,365)+INDEX(Когорта!$N$7:$N$371,365))/B24) -> 0.16960092
A26: Доля рекламы в LTV D365 | B26: =1-B25 -> 0.83039908
A27: Средний DAU в 12-м месяце | B27: =B16 -> 8472.8326
A28: ARPDAU разработчика за год, ₽ | B28: =IF(SUMPRODUCT(B5:B16)=0,0,G17/(SUMPRODUCT(B5:B16)*30)) -> 0.60239108
A29: Доход разработчика за год, ₽ | B29: =G17 -> 1444823.5
A30: Доход разработчика в 12-м месяце, ₽ | B30: =G16 -> 150719.71
A31: Сколько можно платить за установку (окупаемость за 90 дней), ₽ | B31: =B23 -> 3.5193372

Sheet Варианты
A1: Варианты донат-валюты: что будет с доходом
A2: Множители — моя оценка относительно варианта «Узкие алмазы» (= 1). Это не данные: проверять A/B-тестом после выпуска.
A3: Слагаемые LTV D365 берутся с листа «Когорта» (реклама, первые и повторные покупки).
A5: Вариант | B5: × реклама | C5: × первые покупки | D5: × повторные | E5: LTV D365, ₽ | F5: к «Узким алмазам» | G5: Почему такие множители
A6: C. Узкие алмазы (рекомендую) | B6: 1 | C6: 1 | D6: 1 | E6: =$B$14*B6+$B$15*C6+$B$16*D6 -> 5.0801981 | F6: =IF($E$6=0,0,E6/$E$6-1) -> 0 | G6: Монеты за ₽ одной кнопкой в момент нехватки; алмазы — время, спасение, стиль; немного бесплатно — игрок пробует.
A7: A. Всё за рубли, алмазов нет | B7: 1 | C7: 1 | D7: 0.8 | E7: =$B$14*B7+$B$15*C7+$B$16*D7 -> 5.0013769 | F7: =IF($E$6=0,0,E7/$E$6-1) -> -0.015515391 | G7: Первая покупка та же (стартовый, «Горстка»). Повторных меньше: каждое ускорение и продолжение — отдельное окно оплаты; нет «остатка» на счёте, который тянет к следующей покупке; бесплатный игрок не пробует платные вещи.
A8: B. Универсальные алмазы (₽ → 💎 → всё, как в v5) | B8: 1 | C8: 0.9 | D8: 1.05 | E8: =$B$14*B8+$B$15*C8+$B$16*D8 -> 5.0531534 | F8: =IF($E$6=0,0,E8/$E$6-1) -> -0.0053235493 | G8: Монеты только через обмен алмазов: в момент нехватки два шага вместо одного — меньше первых покупок. Повторных чуть больше: всё в одной валюте, остатки тратятся на всё.
A9: D. Как сейчас (билд 24) | B9: 1 | C9: 0.5 | D9: 0.4 | E9: =$B$14*B9+$B$15*C9+$B$16*D9 -> 4.6099844 | F9: =IF($E$6=0,0,E9/$E$6-1) -> -0.092558157 | G9: Монет всегда хватает, продолжения бесплатные, молоток 25 💎: моментов, когда нужна покупка, почти нет (симулятор v7: ~0 против ~17).
A13: LTV D365 «Узкие алмазы» по слагаемым:
A14: реклама | B14: =INDEX(Когорта!$L$7:$L$371,365) -> 4.2185918
A15: первые покупки | B15: =INDEX(Когорта!$M$7:$M$371,365) -> 0.4675
A16: повторные покупки | B16: =INDEX(Когорта!$N$7:$N$371,365) -> 0.3941063
A18: Что получается при годе с этим потоком установок, ₽ разработчику:
A19: =A6 -> C. Узкие алмазы (рекомендую) | B19: =Год!$G$17*E6/$E$6 -> 1444823.5
A20: =A7 -> A. Всё за рубли, алмазов нет | B20: =Год!$G$17*E7/$E$6 -> 1422406.5
A21: =A8 -> B. Универсальные алмазы (₽ → 💎 → всё, как в v5) | B21: =Год!$G$17*E8/$E$6 -> 1437131.9
A22: =A9 -> D. Как сейчас (билд 24) | B22: =Год!$G$17*E9/$E$6 -> 1311093.3

Sheet Каталог
A1: Каталог покупок (вариант «узкие алмазы», экономика v7)
A2: Синие — можно менять. «Прочее, ₽» — оценка стоимости отмен, подсказок, «Тележек +1», скинов, молотков по курсам игры.
A4: ID в консоли | B4: Название | C4: Цена, ₽ | D4: Монет | E4: Алмазов | F4: Что ещё внутри | G4: Прочее, ₽ (оценка) | H4: Ценность, ₽ | I4: Выгода | J4: Доля в первых | K4: Доля в повторных | L4: Когда показывать
A5: coins_s | B5: Горстка монет | C5: 49 | D5: 1000 | E5: 0 | F5: — | G5: 0 | H5: =D5/Допущения!$B$30+E5/Допущения!$B$31+G5 -> 49 | I5: =IF(C5=0,0,H5/C5-1) -> 0 | J5: 0.25 | K5: 0.25 | L5: Окно «Не хватает монет» (ремонт, продолжение), одной кнопкой
A6: coins_m | B6: Мешок монет | C6: 129 | D6: 3000 | E6: 0 | F6: — | G6: 0 | H6: =D6/Допущения!$B$30+E6/Допущения!$B$31+G6 -> 147 | I6: =IF(C6=0,0,H6/C6-1) -> 0.13953488 | J6: 0 | K6: 0.12 | L6: Магазин, «Монеты»; в окне нехватки — если не хватает > 1 000
A7: coins_l | B7: Сундук монет | C7: 299 | D7: 8000 | E7: 0 | F7: — | G7: 0 | H7: =D7/Допущения!$B$30+E7/Допущения!$B$31+G7 -> 392 | I7: =IF(C7=0,0,H7/C7-1) -> 0.31103679 | J7: 0 | K7: 0.04 | L7: Магазин, «Монеты»
A8: coins_xl | B8: Гора монет | C8: 599 | D8: 18000 | E8: 0 | F8: — | G8: 0 | H8: =D8/Допущения!$B$30+E8/Допущения!$B$31+G8 -> 882 | I8: =IF(C8=0,0,H8/C8-1) -> 0.47245409 | J8: 0 | K8: 0.01 | L8: Магазин, «Монеты»
A9: gems_30 | B9: Горсть алмазов | C9: 29 | D9: 0 | E9: 30 | F9: — | G9: 0 | H9: =D9/Допущения!$B$30+E9/Допущения!$B$31+G9 -> 29 | I9: =IF(C9=0,0,H9/C9-1) -> 0 | J9: 0.06 | K9: 0.03 | L9: Окно «Не хватает алмазов» (стройка, продолжение)
A10: gems_90 | B10: Мешочек алмазов | C10: 79 | D10: 0 | E10: 90 | F10: +10 % | G10: 0 | H10: =D10/Допущения!$B$30+E10/Допущения!$B$31+G10 -> 87 | I10: =IF(C10=0,0,H10/C10-1) -> 0.10126582 | J10: 0.04 | K10: 0.08 | L10: Магазин, «Алмазы»
A11: gems_180 | B11: Миска алмазов | C11: 149 | D11: 0 | E11: 180 | F11: +17 % | G11: 0 | H11: =D11/Допущения!$B$30+E11/Допущения!$B$31+G11 -> 174 | I11: =IF(C11=0,0,H11/C11-1) -> 0.16778523 | J11: 0 | K11: 0.07 | L11: Магазин, «Алмазы»
A12: gems_400 | B12: Сундучок алмазов | C12: 299 | D12: 0 | E12: 400 | F12: +29 % | G12: 0 | H12: =D12/Допущения!$B$30+E12/Допущения!$B$31+G12 -> 386.66667 | I12: =IF(C12=0,0,H12/C12-1) -> 0.29319955 | J12: 0 | K12: 0.04 | L12: Магазин, «Алмазы»
A13: gems_850 | B13: Сундук алмазов | C13: 599 | D13: 0 | E13: 850 | F13: +37 % | G13: 0 | H13: =D13/Допущения!$B$30+E13/Допущения!$B$31+G13 -> 821.66667 | I13: =IF(C13=0,0,H13/C13-1) -> 0.37173066 | J13: 0 | K13: 0.01 | L13: Магазин, «Алмазы»
A14: gems_1800 | B14: Тележка алмазов | C14: 1190 | D14: 0 | E14: 1800 | F14: +46 % | G14: 0 | H14: =D14/Допущения!$B$30+E14/Допущения!$B$31+G14 -> 1740 | I14: =IF(C14=0,0,H14/C14-1) -> 0.46218487 | J14: 0 | K14: 0.005 | L14: Магазин, «Алмазы»
A15: starter_pack | B15: Стартовый набор | C15: 99 | D15: 800 | E15: 50 | F15: 10 отмен, 5 подсказок, тележка в цветах | G15: 270 | H15: =D15/Допущения!$B$30+E15/Допущения!$B$31+G15 -> 357.53333 | I15: =IF(C15=0,0,H15/C15-1) -> 2.6114478 | J15: 0.4 | K15: 0 | L15: После 6-го уровня, 72 ч; затем на 20-м и 40-м
A16: piggy | B16: Копилка енота | C16: 99 | D16: 2500 | E16: 0 | F16: 2 000–4 000 монет (в среднем ~2 500); разбить можно с 2 000 | G16: 0 | H16: =D16/Допущения!$B$30+E16/Допущения!$B$31+G16 -> 122.5 | I16: =IF(C16=0,0,H16/C16-1) -> 0.23737374 | J16: 0.1 | K16: 0.12 | L16: Когда в копилке ≥ 1 200; свинка на доме
... A23: set_gold | B23: Золотой магазин | C23: 299 | D23: 3000 | E23: 0 | F23: 3 золотых предмета оформления | G23: 420 | H23: =D23/Допущения!$B$30+E23/Допущения!$B$31+G23 -> 567 | I23: =IF(C23=0,0,H23/C23-1) -> 0.89632107 | J23: 0 | K23: 0.015 | L23: «Гардероб», магазин
B24: Итого долей (должно быть 100 %) | J24: =SUM(J5:J23) -> 1 | K24: =SUM(K5:K23) -> 1.07 | L24: Доли — оценка; после выпуска заменить на долю выручки по товарам из консоли.
B25: Средний чек, ₽ | J25: =IF(J24=0,0,SUMPRODUCT(C5:C23,J5:J23)/J24) -> 93.5 | K25: =IF(K24=0,0,SUMPRODUCT(C5:C23,K5:K23)/K24) -> 145.31308

Sheet Алмазы
A1: Алмазы: откуда, куда и хватает ли бесплатному игроку
A2: Правило: монеты — на прогресс (ремонт, дом, помощь в уровне); алмазы — на время, спасение и стиль. Обмена алмазов на монеты нет.
A4: Бесплатный источник | B4: Алмазов | C4: Как часто, раз в день | D4: Участвует, доля | E4: В день | F4: Комментарий
A5: Испытание дня (победа) | B5: 1 | C5: 1 | D5: 0.6 | E5: =B5*C5*D5 -> 0.6 | F5: v7: 40 монет + 1 💎; с 15-го уровня
A6: Испытание дня: 7 дней подряд | B6: 10 | C6: 0.14285714 | D6: 0.3 | E6: =B6*C6*D6 -> 0.42857143 | F6: v7: 200 монет + 10 💎
A7: Задания недели: последний сундук | B7: 10 | C7: 0.14285714 | D7: 0.5 | E7: =B7*C7*D7 -> 0.71428571 | F7: v7: цели сложнее, закрывается к концу недели
A8: Задания месяца: большой приз | B8: 40 | C8: 0.033333333 | D8: 0.4 | E8: =B8*C8*D8 -> 0.53333333 | F8: v7: 40 💎 + 250 монет
A9: Сундуки серии (5-я и 10-я победа) | B9: 3 | C9: 0.25 | D9: 0.8 | E9: =B9*C9*D9 -> 0.6 | F9: 1 💎 на 5-й, 2 💎 на 10-й; ~10 побед за 4 дня без проигрыша
A10: Альбом: отдел собран | B10: 5 | C10: 0.08 | D10: 1 | E10: =B10*C10*D10 -> 0.4 | F10: v7: 100 монет + 5 💎 вместо +2 % монет навсегда
A11: Звёздный путь | B11: 60 | C11: 0.0066666667 | D11: 1 | E11: =B11*C11*D11 -> 0.4 | F11: ~60 💎 на весь путь
A12: Режимы «Средний»/«Сложный»: район пройден | B12: 4 | C12: 0.1 | D12: 0.5 | E12: =B12*C12*D12 -> 0.2 | F12: +3 / +5 💎 за район; только после «Лёгкого»
A13: Итого бесплатно в день | E13: =SUM(E5:E12) -> 3.8761905
A14: За 30 / 90 / 150 дней | B14: =$E$13*30 -> 116.28571 | C14: =$E$13*90 -> 348.85714 | D14: =$E$13*150 -> 581.42857
A16: Цена «Готово сразу» по оставшемуся времени (Economy.SkipMin / SkipGems)
A17: Осталось, минут | B17: Алмазов | F17: Между точками — линейно
A18: 0 | B18: 0
A19: 5 | B19: 1
A20: 30 | B20: 3
A21: 60 | B21: 5
A22: 240 | B22: 15
A23: 1440 | B23: 60
A24: 10080 | B24: 300
A26: Стройки дома: сколько стоит пропустить каждую целиком
A27: Комната | B27: Стройка, минут | C27: Алмазов, чтобы сразу | F27: Формула — интерполяция по таблице выше
A28: Подсобка | B28: 15 | C28: =IF(B28>=MAX($A$18:$A$24),MAX($B$18:$B$24),ROUND(INDEX($B$18:$B$24,MIN(MATCH(B28,$A$18:$A$24,1),6))+(INDEX($B$18:$B$24,MIN(MATCH(B28,$A$18:$A$24,1),6)+1)-INDEX($B$18:$B$24,MIN(MATCH(B28,$A$18:$A$24,1),6)))*(B28-INDEX($A$18:$A$24,MIN(MATCH(B28,$A$18:$A$24,1),6)))/(INDEX($A$18:$A$24,MIN(MATCH(B28,$A$18:$A$24,1),6)+1)-INDEX($A$18:$A$24,MIN(MATCH(B28,$A$18:$A$24,1),6))),0)) -> 2
A29: Мастерская | B29: 60 | C29: =IF(B29>=MAX($A$18:$A$24),MAX($B$18:$B$24),ROUND(INDEX($B$18:$B$24,MIN(MATCH(B29,$A$18:$A$24,1),6))+(INDEX($B$18:$B$24,MIN(MATCH(B29,$A$18:$A$24,1),6)+1)-INDEX($B$18:$B$24,MIN(MATCH(B29,$A$18:$A$24,1),6)))*(B29-INDEX($A$18:$A$24,MIN(MATCH(B29,$A$18:$A$24,1),6)))/(INDEX($A$18:$A$24,MIN(MATCH(B29,$A$18:$A$24,1),6)+1)-INDEX($A$18:$A$24,MIN(MATCH(B29,$A$18:$A$24,1),6))),0)) -> 5
A30: Стойка у входа | B30: 180 | C30: =IF(B30>=MAX($A$18:$A$24),MAX($B$18:$B$24),ROUND(INDEX($B$18:$B$24,MIN(MATCH(B30,$A$18:$A$24,1),6))+(INDEX($B$18:$B$24,MIN(MATCH(B30,$A$18:$A$24,1),6)+1)-INDEX($B$18:$B$24,MIN(MATCH(B30,$A$18:$A$24,1),6)))*(B30-INDEX($A$18:$A$24,MIN(MATCH(B30,$A$18:$A$24,1),6)))/(INDEX($A$18:$A$24,MIN(MATCH(B30,$A$18:$A$24,1),6)+1)-INDEX($A$18:$A$24,MIN(MATCH(B30,$A$18:$A$24,1),6))),0)) -> 12
A31: Кладовая | B31: 360 | C31: =IF(B31>=MAX($A$18:$A$24),MAX($B$18:$B$24),ROUND(INDEX($B$18:$B$24,MIN(MATCH(B31,$A$18:$A$24,1),6))+(INDEX($B$18:$B$24,MIN(MATCH(B31,$A$18:$A$24,1),6)+1)-INDEX($B$18:$B$24,MIN(MATCH(B31,$A$18:$A$24,1),6)))*(B31-INDEX($A$18:$A$24,MIN(MATCH(B31,$A$18:$A$24,1),6)))/(INDEX($A$18:$A$24,MIN(MATCH(B31,$A$18:$A$24,1),6)+1)-INDEX($A$18:$A$24,MIN(MATCH(B31,$A$18:$A$24,1),6))),0)) -> 20
A32: Холодильный цех | B32: 600 | C32: =IF(B32>=MAX($A$18:$A$24),MAX($B$18:$B$24),ROUND(INDEX($B$18:$B$24,MIN(MATCH(B32,$A$18:$A$24,1),6))+(INDEX($B$18:$B$24,MIN(MATCH(B32,$A$18:$A$24,1),6)+1)-INDEX($B$18:$B$24,MIN(MATCH(B32,$A$18:$A$24,1),6)))*(B32-INDEX($A$18:$A$24,MIN(MATCH(B32,$A$18:$A$24,1),6)))/(INDEX($A$18:$A$24,MIN(MATCH(B32,$A$18:$A$24,1),6)+1)-INDEX($A$18:$A$24,MIN(MATCH(B32,$A$18:$A$24,1),6))),0)) -> 29
A33: Рекламный отдел | B33: 960 | C33: =IF(B33>=MAX($A$18:$A$24),MAX($B$18:$B$24),ROUND(INDEX($B$18:$B$24,MIN(MATCH(B33,$A$18:$A$24,1),6))+(INDEX($B$18:$B$24,MIN(MATCH(B33,$A$18:$A$24,1),6)+1)-INDEX($B$18:$B$24,MIN(MATCH(B33,$A$18:$A$24,1),6)))*(B33-INDEX($A$18:$A$24,MIN(MATCH(B33,$A$18:$A$24,1),6)))/(INDEX($A$18:$A$24,MIN(MATCH(B33,$A$18:$A$24,1),6)+1)-INDEX($A$18:$A$24,MIN(MATCH(B33,$A$18:$A$24,1),6))),0)) -> 42
A34: Ночной пост | B34: 1440 | C34: =IF(B34>=MAX($A$18:$A$24),MAX($B$18:$B$24),ROUND(INDEX($B$18:$B$24,MIN(MATCH(B34,$A$18:$A$24,1),6))+(INDEX($B$18:$B$24,MIN(MATCH(B34,$A$18:$A$24,1),6)+1)-INDEX($B$18:$B$24,MIN(MATCH(B34,$A$18:$A$24,1),6)))*(B34-INDEX($A$18:$A$24,MIN(MATCH(B34,$A$18:$A$24,1),6)))/(INDEX($A$18:$A$24,MIN(MATCH(B34,$A$18:$A$24,1),6)+1)-INDEX($A$18:$A$24,MIN(MATCH(B34,$A$18:$A$24,1),6))),0)) -> 60
A35: Грузовая рампа | B35: 2160 | C35: =IF(B35>=MAX($A$18:$A$24),MAX($B$18:$B$24),ROUND(INDEX($B$18:$B$24,MIN(MATCH(B35,$A$18:$A$24,1),6))+(INDEX($B$18:$B$24,MIN(MATCH(B35,$A$18:$A$24,1),6)+1)-INDEX($B$18:$B$24,MIN(MATCH(B35,$A$18:$A$24,1),6)))*(B35-INDEX($A$18:$A$24,MIN(MATCH(B35,$A$18:$A$24,1),6)))/(INDEX($A$18:$A$24,MIN(MATCH(B35,$A$18:$A$24,1),6)+1)-INDEX($A$18:$A$24,MIN(MATCH(B35,$A$18:$A$24,1),6))),0)) -> 80
A36: Буфет | B36: 3600 | C36: =IF(B36>=MAX($A$18:$A$24),MAX($B$18:$B$24),ROUND(INDEX($B$18:$B$24,MIN(MATCH(B36,$A$18:$A$24,1),6))+(INDEX($B$18:$B$24,MIN(MATCH(B36,$A$18:$A$24,1),6)+1)-INDEX($B$18:$B$24,MIN(MATCH(B36,$A$18:$A$24,1),6)))*(B36-INDEX($A$18:$A$24,MIN(MATCH(B36,$A$18:$A$24,1),6)))/(INDEX($A$18:$A$24,MIN(MATCH(B36,$A$18:$A$24,1),6)+1)-INDEX($A$18:$A$24,MIN(MATCH(B36,$A$18:$A$24,1),6))),0)) -> 120
A37: Кабинет управляющего | B37: 5760 | C37: =IF(B37>=MAX($A$18:$A$24),MAX($B$18:$B$24),ROUND(INDEX($B$18:$B$24,MIN(MATCH(B37,$A$18:$A$24,1),6))+(INDEX($B$18:$B$24,MIN(MATCH(B37,$A$18:$A$24,1),6)+1)-INDEX($B$18:$B$24,MIN(MATCH(B37,$A$18:$A$24,1),6)))*(B37-INDEX($A$18:$A$24,MIN(MATCH(B37,$A$18:$A$24,1),6)))/(INDEX($A$18:$A$24,MIN(MATCH(B37,$A$18:$A$24,1),6)+1)-INDEX($A$18:$A$24,MIN(MATCH(B37,$A$18:$A$24,1),6))),0)) -> 180
A38: Терраса | B38: 10080 | C38: =IF(B38>=MAX($A$18:$A$24),MAX($B$18:$B$24),ROUND(INDEX($B$18:$B$24,MIN(MATCH(B38,$A$18:$A$24,1),6))+(INDEX($B$18:$B$24,MIN(MATCH(B38,$A$18:$A$24,1),6)+1)-INDEX($B$18:$B$24,MIN(MATCH(B38,$A$18:$A$24,1),6)))*(B38-INDEX($A$18:$A$24,MIN(MATCH(B38,$A$18:$A$24,1),6)))/(INDEX($A$18:$A$24,MIN(MATCH(B38,$A$18:$A$24,1),6)+1)-INDEX($A$18:$A$24,MIN(MATCH(B38,$A$18:$A$24,1),6))),0)) -> 300
A39: Пропустить все стройки дома | C39: =SUM(C28:C38) -> 850
A41: На что ещё тратятся алмазы
A42: Трата | B42: Алмазов | F42: Зачем
A43: Продолжение, когда монет не хватает (1-е / районы 1–5) | B43: 15 | F43: кнопка показывает монеты, если хватает, иначе алмазы — никогда обе
A44: Продолжение 2-е / 3-е (районы 1–5) | B44: 35 | F44: 3-е — 70 💎; районы 6–10 — 20/45/90, 11–15 — 25/60/120
...

Sheet Когорта
A1: Когорта: один установивший игрок, 365 дней жизни (все суммы — на одну установку)
A2: Удержание между опорными днями — по степенной кривой (линейно в логарифмах). Возраст 0 — день установки. | S2: Опорные точки удержания
S3: 1 | T3: 7 | U3: 30 | V3: 90 | W3: 180 | X3: 365
S4: =Допущения!$B$7 -> 0.3 | T4: =Допущения!$B$8 -> 0.12 | U4: =Допущения!$B$9 -> 0.05 | V4: =Допущения!$B$10 -> 0.022 | W4: =Допущения!$B$11 -> 0.012 | X4: =Допущения!$B$12 -> 0.005
A6: Возраст, дн | B6: Удержание | C6: Накопл. удержание | D6: Заплатили (накопл.) | E6: Новые платящие | F6: Активные платящие | G6: Реклама, ₽ (вал) | H6: Первые покупки, ₽ (вал) | I6: Повторные, ₽ (вал) | J6: Доход разработчика, ₽ | K6: LTV разработчика, ₽ | L6: LTV: реклама | M6: LTV: первые покупки | N6: LTV: повторные | O6: LTV валовый, ₽ | P6: Накопл. активных платящих | Q6: Сегм.
A7: 0 | B7: 1 | C7: =B7 -> 1 | D7: =Допущения!$B$19*(1-EXP(-Допущения!$B$26*(A7+1))) -> 0.00099654639 | E7: =D7 -> 0.00099654639 | F7: =D7*MIN(1,B7*Допущения!$B$21) -> 0.00099654639 | G7: =((B7-F7*Допущения!$B$23)*Допущения!$B$13*Допущения!$B$15+B7*Допущения!$B$14*Допущения!$B$16)/1000 -> 0.98494619 | H7: =E7*Допущения!$B$27 -> 0.093177088 | I7: =F7*Допущения!$B$22/30*Допущения!$B$28 -> 0.004827041 | J7: =G7*Допущения!$B$17+(H7+I7)*Допущения!$B$18 -> 0.54147516 | K7: =J7 -> 0.54147516 | L7: =G7*Допущения!$B$17 -> 0.49247309 | M7: =H7*Допущения!$B$18 -> 0.046588544 | N7: =I7*Допущения!$B$18 -> 0.0024135205 | O7: =G7+H7+I7 -> 1.0829503 | P7: =F7 -> 0.00099654639 | Q7: 1
A8: 1 | B8: =INDEX($S$4:$X$4,Q8)*(INDEX($S$4:$X$4,Q8+1)/INDEX($S$4:$X$4,Q8))^((LN(A8)-LN(INDEX($S$3:$X$3,Q8)))/(LN(INDEX($S$3:$X$3,Q8+1))-LN(INDEX($S$3:$X$3,Q8)))) -> 0.3 | C8: =C7+B8 -> 1.3 | D8: =Допущения!$B$19*(1-EXP(-Допущения!$B$26*(A8+1))) -> 0.0018937823 | E8: =D8-D7 -> 0.00089723592 | F8: =D8*MIN(1,B8*Допущения!$B$21) -> 0.0014203367 | G8: =((B8-F8*Допущения!$B$23)*Допущения!$B$13*Допущения!$B$15+B8*Допущения!$B$14*Допущения!$B$16)/1000 -> 0.2954233 | H8: =E8*Допущения!$B$27 -> 0.083891559 | I8: =F8*Допущения!$B$22/30*Допущения!$B$28 -> 0.0068797837 | J8: =G8*Допущения!$B$17+(H8+I8)*Допущения!$B$18 -> 0.19309732 | K8: =K7+J8 -> 0.73457248 | L8: =L7+G8*Допущения!$B$17 -> 0.64018474 | M8: =M7+H8*Допущения!$B$18 -> 0.088534323 | N8: =N7+I8*Допущения!$B$18 -> 0.0058534123 | O8: =O7+G8+H8+I8 -> 1.469145 | P8: =P7+F8 -> 0.0024168831 | Q8: =MIN(MATCH(A8,$S$3:$X$3,1),5) -> 1
A9: 2 | B9: =INDEX($S$4:$X$4,Q9)*(INDEX($S$4:$X$4,Q9+1)/INDEX($S$4:$X$4,Q9))^((LN(A9)-LN(INDEX($S$3:$X$3,Q9)))/(LN(INDEX($S$3:$X$3,Q9+1))-LN(INDEX($S$3:$X$3,Q9)))) -> 0.21645726 | C9: =C8+B9 -> 1.5164573 | D9: =Допущения!$B$19*(1-EXP(-Допущения!$B$26*(A9+1))) -> 0.0027016045 | E9: =D9-D8 -> 0.0008078222 | F9: =D9*MIN(1,B9*Допущения!$B$21) -> 0.0014619548 | G9: =((B9-F9*Допущения!$B$23)*Допущения!$B$13*Допущения!$B$15+B9*Допущения!$B$14*Допущения!$B$16)/1000 -> 0.21313146 | H9: =E9*Допущения!$B$27 -> 0.075531376 | I9: =F9*Допущения!$B$22/30*Допущения!$B$28 -> 0.007081372 | J9: =G9*Допущения!$B$17+(H9+I9)*Допущения!$B$18 -> 0.1478721 | K9: =K8+J9 -> 0.88244458 | L9: =L8+G9*Допущения!$B$17 -> 0.74675047 | M9: =M8+H9*Допущения!$B$18 -> 0.12630001 | N9: =N8+I9*Допущения!$B$18 -> 0.0093940984 | O9: =O8+G9+H9+I9 -> 1.7648892 | P9: =P8+F9 -> 0.0038788379 | Q9: =MIN(MATCH(A9,$S$3:$X$3,1),5) -> 1
A10: 3 | B10: =INDEX($S$4:$X$4,Q10)*(INDEX($S$4:$X$4,Q10+1)/INDEX($S$4:$X$4,Q10))^((LN(A10)-LN(INDEX($S$3:$X$3,Q10)))/(LN(INDEX($S$3:$X$3,Q10+1))-LN(INDEX($S$3:$X$3,Q10)))) -> 0.17883572 | C10: =C9+B10 -> 1.695293 | D10: =Допущения!$B$19*(1-EXP(-Допущения!$B$26*(A10+1))) -> 0.0034289235 | E10: =D10-D9 -> 0.00072731897 | F10: =D10*MIN(1,B10*Допущения!$B$21) -> 0.001533035 | G10: =((B10-F10*Допущения!$B$23)*Допущения!$B$13*Допущения!$B$15+B10*Допущения!$B$14*Допущения!$B$16)/1000 -> 0.1760704 | H10: =E10*Допущения!$B$27 -> 0.068004324 | I10: =F10*Допущения!$B$22/30*Допущения!$B$28 -> 0.007425668 | J10: =G10*Допущения!$B$17+(H10+I10)*Допущения!$B$18 -> 0.12575019 | K10: =K9+J10 -> 1.0081948 | L10: =L9+G10*Допущения!$B$17 -> 0.83478567 | M10: =M9+H10*Допущения!$B$18 -> 0.16030217 | N10: =N9+I10*Допущения!$B$18 -> 0.013106932 | O10: =O9+G10+H10+I10 -> 2.0163896 | P10: =P9+F10 -> 0.0054118729 | Q10: =MIN(MATCH(A10,$S$3:$X$3,1),5) -> 1
A11: 4 | B11: =INDEX($S$4:$X$4,Q11)*(INDEX($S$4:$X$4,Q11+1)/INDEX($S$4:$X$4,Q11))^((LN(A11)-LN(INDEX($S$3:$X$3,Q11)))/(LN(INDEX($S$3:$X$3,Q11+1))-LN(INDEX($S$3:$X$3,Q11)))) -> 0.15617916 | C11: =C10+B11 -> 1.8514721 | D11: =Допущения!$B$19*(1-EXP(-Допущения!$B$26*(A11+1))) -> 0.0040837617 | E11: =D11-D10 -> 0.00065483826 | F11: =D11*MIN(1,B11*Допущения!$B$21) -> 0.0015944962 | G11: =((B11-F11*Допущения!$B$23)*Допущения!$B$13*Допущения!$B$15+B11*Допущения!$B$14*Допущения!$B$16)/1000 -> 0.15375037 | H11: =E11*Допущения!$B$27 -> 0.061227377 | I11: =F11*Допущения!$B$22/30*Допущения!$B$28 -> 0.0077233718 | J11: =G11*Допущения!$B$17+(H11+I11)*Допущения!$B$18 -> 0.11135056 | K11: =K10+J11 -> 1.1195453 | L11: =L10+G11*Допущения!$B$17 -> 0.91166086 | M11: =M10+H11*Допущения!$B$18 -> 0.19091586 | N11: =N10+I11*Допущения!$B$18 -> 0.016968618 | O11: =O10+G11+H11+I11 -> 2.2390907 | P11: =P10+F11 -> 0.0070063691 | Q11: =MIN(MATCH(A11,$S$3:$X$3,1),5) -> 1
A12: 5 | B12: =INDEX($S$4:$X$4,Q12)*(INDEX($S$4:$X$4,Q12+1)/INDEX($S$4:$X$4,Q12))^((LN(A12)-LN(INDEX($S$3:$X$3,Q12)))/(LN(INDEX($S$3:$X$3,Q12+1))-LN(INDEX($S$3:$X$3,Q12)))) -> 0.14060153 | C12: =C11+B12 -> 1.9920737 | D12: =Допущения!$B$19*(1-EXP(-Допущения!$B$26*(A12+1))) -> 0.0046733423 | E12: =D12-D11 -> 0.00058958059 | F12: =D12*MIN(1,B12*Допущения!$B$21) -> 0.0016426977 | G12: =((B12-F12*Допущения!$B$23)*Допущения!$B$13*Допущения!$B$15+B12*Допущения!$B$14*Допущения!$B$16)/1000 -> 0.1384038 | H12: =E12*Допущения!$B$27 -> 0.055125785 | I12: =F12*Допущения!$B$22/30*Допущения!$B$28 -> 0.0079568492 | J12: =G12*Допущения!$B$17+(H12+I12)*Допущения!$B$18 -> 0.10074322 | K12: =K11+J12 -> 1.2202886 | L12: =L11+G12*Допущения!$B$17 -> 0.98086276 | M12: =M11+H12*Допущения!$B$18 -> 0.21847875 | N12: =N11+I12*Допущения!$B$18 -> 0.020947043 | O12: =O11+G12+H12+I12 -> 2.4405771 | P12: =P11+F12 -> 0.0086490668 | Q12: =MIN(MATCH(A12,$S$3:$X$3,1),5) -> 1
A13: 6 | B13: =INDEX($S$4:$X$4,Q13)*(INDEX($S$4:$X$4,Q13+1)/INDEX($S$4:$X$4,Q13))^((LN(A13)-LN(INDEX($S$3:$X$3,Q13)))/(LN(INDEX($S$3:$X$3,Q13+1))-LN(INDEX($S$3:$X$3,Q13)))) -> 0.1290343 | C13: =C12+B13 -> 2.121108 | D13: =Допущения!$B$19*(1-EXP(-Допущения!$B$26*(A13+1))) -> 0.0052041685 | E13: =D13-D12 -> 0.00053082615 | F13: =D13*MIN(1,B13*Допущения!$B$21) -> 0.0016787906 | G13: =((B13-F13*Допущения!$B$23)*Допущения!$B$13*Допущения!$B$15+B13*Допущения!$B$14*Допущения!$B$16)/1000 -> 0.12700813 | H13: =E13*Допущения!$B$27 -> 0.049632245 | I13: =F13*Допущения!$B$22/30*Допущения!$B$28 -> 0.0081316746 | J13: =G13*Допущения!$B$17+(H13+I13)*Допущения!$B$18 -> 0.092386025 | K13: =K12+J13 -> 1.3126746 | L13: =L12+G13*Допущения!$B$17 -> 1.0443668 | M13: =M12+H13*Допущения!$B$18 -> 0.24329488 | N13: =N12+I13*Допущения!$B$18 -> 0.02501288 | O13: =O12+G13+H13+I13 -> 2.6253492 | P13: =P12+F13 -> 0.010327857 | Q13: =MIN(MATCH(A13,$S$3:$X$3,1),5) -> 1
A14: 7 | B14: =INDEX($S$4:$X$4,Q14)*(INDEX($S$4:$X$4,Q14+1)/INDEX($S$4:$X$4,Q14))^((LN(A14)-LN(INDEX($S$3:$X$3,Q14)))/(LN(INDEX($S$3:$X$3,Q14+1))-LN(INDEX($S$3:$X$3,Q14)))) -> 0.12 | C14: =C13+B14 -> 2.241108 | D14: =Допущения!$B$19*(1-EXP(-Допущения!$B$26*(A14+1))) -> 0.0056820953 | E14: =D14-D13 -> 0.00047792686 | F14: =D14*MIN(1,B14*Допущения!$B$21) -> 0.0017046286 | G14: =((B14-F14*Допущения!$B$23)*Допущения!$B$13*Допущения!$B$15+B14*Допущения!$B$14*Допущения!$B$16)/1000 -> 0.11810795 | H14: =E14*Допущения!$B$27 -> 0.044686161 | I14: =F14*Допущения!$B$22/30*Допущения!$B$28 -> 0.008256828 | J14: =G14*Допущения!$B$17+(H14+I14)*Допущения!$B$18 -> 0.08552547 | K14: =K13+J14 -> 1.3982 | L14: =L13+G14*Допущения!$B$17 -> 1.1034208 | M14: =M13+H14*Допущения!$B$18 -> 0.26563796 | N14: =N13+I14*Допущения!$B$18 -> 0.029141294 | O14: =O13+G14+H14+I14 -> 2.7964001 | P14: =P13+F14 -> 0.012032486 | Q14: =MIN(MATCH(A14,$S$3:$X$3,1),5) -> 2
A15: 8 | B15: =INDEX($S$4:$X$4,Q15)*(INDEX($S$4:$X$4,Q15+1)/INDEX($S$4:$X$4,Q15))^((LN(A15)-LN(INDEX($S$3:$X$3,Q15)))/(LN(INDEX($S$3:$X$3,Q15+1))-LN(INDEX($S$3:$X$3,Q15)))) -> 0.11073746 | C15: =C14+B15 -> 2.3518454 | D15: =Допущения!$B$19*(1-EXP(-Допущения!$B$26*(A15+1))) -> 0.0061123946 | E15: =D15-D14 -> 0.00043029923 | F15: =D15*MIN(1,B15*Допущения!$B$21) -> 0.0016921777 | G15: =((B15-F15*Допущения!$B$23)*Допущения!$B$13*Допущения!$B$15+B15*Допущения!$B$14*Допущения!$B$16)/1000 -> 0.10898502 | H15: =E15*Допущения!$B$27 -> 0.040232978 | I15: =F15*Допущения!$B$22/30*Допущения!$B$28 -> 0.0081965185 | J15: =G15*Допущения!$B$17+(H15+I15)*Допущения!$B$18 -> 0.07870726 | K15: =K14+J15 -> 1.4769073 | L15: =L14+G15*Допущения!$B$17 -> 1.1579133 | M15: =M14+H15*Допущения!$B$18 -> 0.28575445 | N15: =N14+I15*Допущения!$B$18 -> 0.033239553 | O15: =O14+G15+H15+I15 -> 2.9538146 | P15: =P14+F15 -> 0.013724664 | Q15: =MIN(MATCH(A15,$S$3:$X$3,1),5) -> 2
A16: 9 | B16: =INDEX($S$4:$X$4,Q16)*(INDEX($S$4:$X$4,Q16+1)/INDEX($S$4:$X$4,Q16))^((LN(A16)-LN(INDEX($S$3:$X$3,Q16)))/(LN(INDEX($S$3:$X$3,Q16+1))-LN(INDEX($S$3:$X$3,Q16)))) -> 0.10316261 | C16: =C15+B16 -> 2.455008 | D16: =Допущения!$B$19*(1-EXP(-Допущения!$B$26*(A16+1))) -> 0.0064998125 | E16: =D16-D15 -> 0.00038741792 | F16: =D16*MIN(1,B16*Допущения!$B$21) -> 0.0016763441 | G16: =((B16-F16*Допущения!$B$23)*Допущения!$B$13*Допущения!$B$15+B16*Допущения!$B$14*Допущения!$B$16)/1000 -> 0.10152465 | H16: =E16*Допущения!$B$27 -> 0.036223575 | I16: =F16*Допущения!$B$22/30*Допущения!$B$28 -> 0.0081198244 | J16: =G16*Допущения!$B$17+(H16+I16)*Допущения!$B$18 -> 0.072934026 | K16: =K15+J16 -> 1.5498413 | L16: =L15+G16*Допущения!$B$17 -> 1.2086756 | M16: =M15+H16*Допущения!$B$18 -> 0.30386623 | N16: =N15+I16*Допущения!$B$18 -> 0.037299466 | O16: =O15+G16+H16+I16 -> 3.0996827 | P16: =P15+F16 -> 0.015401008 | Q16: =MIN(MATCH(A16,$S$3:$X$3,1),5) -> 2
A17: 10 | B17: =INDEX($S$4:$X$4,Q17)*(INDEX($S$4:$X$4,Q17+1)/INDEX($S$4:$X$4,Q17))^((LN(A17)-LN(INDEX($S$3:$X$3,Q17)))/(LN(INDEX($S$3:$X$3,Q17+1))-LN(INDEX($S$3:$X$3,Q17)))) -> 0.096826813 | C17: =C16+B17 -> 2.5518349 | D17: =Допущения!$B$19*(1-EXP(-Допущения!$B$26*(A17+1))) -> 0.0068486224 | E17: =D17-D16 -> 0.00034880992 | F17: =D17*MIN(1,B17*Допущения!$B$21) -> 0.0016578257 | G17: =((B17-F17*Допущения!$B$23)*Допущения!$B$13*Допущения!$B$15+B17*Допущения!$B$14*Допущения!$B$16)/1000 -> 0.095284889 | H17: =E17*Допущения!$B$27 -> 0.032613728 | I17: =F17*Допущения!$B$22/30*Допущения!$B$28 -> 0.0080301256 | J17: =G17*Допущения!$B$17+(H17+I17)*Допущения!$B$18 -> 0.067964371 | K17: =K16+J17 -> 1.6178057 | L17: =L16+G17*Допущения!$B$17 -> 1.2563181 | M17: =M16+H17*Допущения!$B$18 -> 0.3201731 | N17: =N16+I17*Допущения!$B$18 -> 0.041314528 | O17: =O16+G17+H17+I17 -> 3.2356114 | P17: =P16+F17 -> 0.017058833 | Q17: =MIN(MATCH(A17,$S$3:$X$3,1),5) -> 2
A18: 11 | B18: =INDEX($S$4:$X$4,Q18)*(INDEX($S$4:$X$4,Q18+1)/INDEX($S$4:$X$4,Q18))^((LN(A18)-LN(INDEX($S$3:$X$3,Q18)))/(LN(INDEX($S$3:$X$3,Q18+1))-LN(INDEX($S$3:$X$3,Q18)))) -> 0.091431262 | C18: =C17+B18 -> 2.6432661 | D18: =Допущения!$B$19*(1-EXP(-Допущения!$B$26*(A18+1))) -> 0.0071626718 | E18: =D18-D17 -> 0.0003140494 | F18: =D18*MIN(1,B18*Допущения!$B$21) -> 0.0016372303 | G18: =((B18-F18*Допущения!$B$23)*Допущения!$B$13*Допущения!$B$15+B18*Допущения!$B$14*Допущения!$B$16)/1000 -> 0.089971382 | H18: =E18*Допущения!$B$27 -> 0.029363619 | I18: =F18*Допущения!$B$22/30*Допущения!$B$28 -> 0.0079303661 | J18: =G18*Допущения!$B$17+(H18+I18)*Допущения!$B$18 -> 0.063632683 | K18: =K17+J18 -> 1.6814384 | L18: =L17+G18*Допущения!$B$17 -> 1.3013038 | M18: =M17+H18*Допущения!$B$18 -> 0.33485491 | N18: =N17+I18*Допущения!$B$18 -> 0.045279711 | O18: =O17+G18+H18+I18 -> 3.3628768 | P18: =P17+F18 -> 0.018696064 | Q18: =MIN(MATCH(A18,$S$3:$X$3,1),5) -> 2
A19: 12 | B19: =INDEX($S$4:$X$4,Q19)*(INDEX($S$4:$X$4,Q19+1)/INDEX($S$4:$X$4,Q19))^((LN(A19)-LN(INDEX($S$3:$X$3,Q19)))/(LN(INDEX($S$3:$X$3,Q19+1))-LN(INDEX($S$3:$X$3,Q19)))) -> 0.086768471 | C19: =C18+B19 -> 2.7300346 | D19: =Допущения!$B$19*(1-EXP(-Допущения!$B$26*(A19+1))) -> 0.0074454247 | E19: =D19-D18 -> 0.00028275292 | F19: =D19*MIN(1,B19*Допущения!$B$21) -> 0.0016150703 | G19: =((B19-F19*Допущения!$B$23)*Допущения!$B$13*Допущения!$B$15+B19*Допущения!$B$14*Допущения!$B$16)/1000 -> 0.085379731 | H19: =E19*Допущения!$B$27 -> 0.026437398 | I19: =F19*Допущения!$B$22/30*Допущения!$B$28 -> 0.0078230282 | J19: =G19*Допущения!$B$17+(H19+I19)*Допущения!$B$18 -> 0.059820078 | K19: =K18+J19 -> 1.7412585 | L19: =L18+G19*Допущения!$B$17 -> 1.3439936 | M19: =M18+H19*Допущения!$B$18 -> 0.34807361 | N19: =N18+I19*Допущения!$B$18 -> 0.049191226 | O19: =O18+G19+H19+I19 -> 3.4825169 | P19: =P18+F19 -> 0.020311134 | Q19: =MIN(MATCH(A19,$S$3:$X$3,1),5) -> 2
... A371: 364 | B371: =INDEX($S$4:$X$4,Q371)*(INDEX($S$4:$X$4,Q371+1)/INDEX($S$4:$X$4,Q371))^((LN(A371)-LN(INDEX($S$3:$X$3,Q371)))/(LN(INDEX($S$3:$X$3,Q371+1))-LN(INDEX($S$3:$X$3,Q371)))) -> 0.0050170164 | C371: =C370+B371 -> 8.5745898 | D371: =Допущения!$B$19*(1-EXP(-Допущения!$B$26*(A371+1))) -> 0.01 | E371: =D371-D370 -> 0 | F371: =D371*MIN(1,B371*Допущения!$B$21) -> 0.00012542541 | G371: =((B371-F371*Допущения!$B$23)*Допущения!$B$13*Допущения!$B$15+B371*Допущения!$B$14*Допущения!$B$16)/1000 -> 0.0049349882 | H371: =E371*Допущения!$B$27 -> 0 | I371: =F371*Допущения!$B$22/30*Допущения!$B$28 -> 0.00060753178 | J371: =G371*Допущения!$B$17+(H371+I371)*Допущения!$B$18 -> 0.00277126 | K371: =K370+J371 -> 5.0801981 | L371: =L370+G371*Допущения!$B$17 -> 4.2185918 | M371: =M370+H371*Допущения!$B$18 -> 0.4675 | N371: =N370+I371*Допущения!$B$18 -> 0.3941063 | O371: =O370+G371+H371+I371 -> 10.160396 | P371: =P370+F371 -> 0.16272711 | Q371: =MIN(MATCH(A371,$S$3:$X$3,1),5) -> 5
